<mujoco model="mo_alle_drone">
    <compiler angle="degree" meshdir="../stl/"  texturedir="../textures/" />
    <!-- <option gravity="0 0 0"/> -->
    <option gravity="0 0 -9.81"/>
    <!-- <option gravity="0 0 -9.81" collision="predefined"/> -->
    <size njmax="5000" nconmax="1000" />
    <asset>
        <texture type="skybox" builtin="gradient" rgb1="0.44 0.85 0.56" rgb2="0.46 0.87 0.58" width="32" height="32"></texture>
        <texture name="texture_block" file="block.png" gridsize="3 4" gridlayout=".U..LFRB.D.."></texture>
        <mesh name="A0509_0_0" file="A0509_0_0.stl" scale="0.001 0.001 0.001" />
        <mesh name="A0509_1_0" file="A0509_1_0.stl" scale="0.001 0.001 0.001" />
        <mesh name="A0509_1_1" file="A0509_1_1.stl" scale="0.001 0.001 0.001" />
        <mesh name="A0509_1_2" file="A0509_1_2.stl" scale="0.001 0.001 0.001" />
        <mesh name="A0509_2_0" file="A0509_2_0.stl" scale="0.001 0.001 0.001" />
        <mesh name="A0509_2_1" file="A0509_2_1.stl" scale="0.001 0.001 0.001" />
        <mesh name="A0509_2_2" file="A0509_2_2.stl" scale="0.001 0.001 0.001" />
        <mesh name="A0509_3_0" file="A0509_3_0.stl" scale="0.001 0.001 0.001" />
        <mesh name="A0509_3_1" file="A0509_3_1.stl" scale="0.001 0.001 0.001" />
        <mesh name="A0509_4_0" file="A0509_4_0.stl" scale="0.001 0.001 0.001" />
        <mesh name="A0509_4_1" file="A0509_4_1.stl" scale="0.001 0.001 0.001" />
        <mesh name="A0509_5_0" file="A0509_5_0.stl" scale="0.001 0.001 0.001" />
        <mesh name="A0509_5_1" file="A0509_5_1.stl" scale="0.001 0.001 0.001" />
        <mesh name="A0509_6_0" file="A0509_6_0.stl" scale="0.001 0.001 0.001" />
        <mesh name="base_link" file="alle_base_link.STL" />
        <mesh name="link_0.0" file="link_0.0.STL" />
        <mesh name="link_1.0" file="link_1.0.STL" />
        <mesh name="link_2.0" file="link_2.0.STL" />
        <mesh name="link_3.0" file="link_3.0.STL" />
        <mesh name="link_3.0_tip" file="link_3.0_tip.STL" />
        <mesh name="link_12.0_right" file="link_12.0_right.STL" />
        <mesh name="link_13.0" file="link_13.0.STL" />
        <mesh name="link_14.0" file="link_14.0.STL" />
        <mesh name="link_15.0" file="link_15.0.STL" />
        <mesh name="link_15.0_tip" file="link_15.0_tip.STL" />
        <material name="block_mat" specular="0" shininess="0.5" reflectance="0" rgba="0.2 0.2 0.2 1"></material>
        <material name="table_mat" specular="0" shininess="0.5" reflectance="0" rgba="0.93 0.93 0.93 1"></material>
        <!-- <skin name="table_mat" file="block.png" rgba="0.93 0.93 0.93 1" ></skin> -->
    </asset>

    
    <contact>
        <!-- <pair geom1="ball" geom2="table"></pair>
        <pair geom1="target" geom2="table"></pair> -->
        <!-- <pair geom1="cup" geom2="table"></pair> -->
    </contact>

    <equality>
        <weld body1="mocap" body2="alle_base_body" solimp="0.9 0.95 0.001" solref="0.02 1"></weld>
    </equality>

    <actuator>
        <!-- <position name="joint6" joint="joint6" ctrlrange="0 1" kp="0.1" forcerange="-1 1"></position> -->
        <position name="actuator:joint_0.0" joint="joint_0.0" ctrlrange="0 1" kp="10" forcerange="-1 1"></position>
        <position name="actuator:joint_1.0" joint="joint_1.0" ctrlrange="0 1" kp="10" forcerange="-1 1"></position>
        <position name="actuator:joint_2.0" joint="joint_2.0" ctrlrange="0 1" kp="10" forcerange="-1 1"></position>
        <position name="actuator:joint_3.0" joint="joint_3.0" ctrlrange="0 1" kp="10" forcerange="-1 1"></position>
        <position name="actuator:joint_4.0" joint="joint_4.0" ctrlrange="0 1" kp="10" forcerange="-1 1"></position>
        <position name="actuator:joint_5.0" joint="joint_5.0" ctrlrange="0 1" kp="10" forcerange="-1 1"></position>
        <position name="actuator:joint_6.0" joint="joint_6.0" ctrlrange="0 1" kp="10" forcerange="-1 1"></position>
        <position name="actuator:joint_7.0" joint="joint_7.0" ctrlrange="0 1" kp="10" forcerange="-1 1"></position>
        <position name="actuator:joint_8.0" joint="joint_8.0" ctrlrange="0 1" kp="10" forcerange="-1 1"></position>
        <position name="actuator:joint_9.0" joint="joint_9.0" ctrlrange="0 1" kp="10" forcerange="-1 1"></position>
        <position name="actuator:joint_10.0" joint="joint_10.0" ctrlrange="0 1" kp="10" forcerange="-1 1"></position>
        <position name="actuator:joint_11.0" joint="joint_11.0" ctrlrange="0 1" kp="10" forcerange="-1 1"></position>
        <position name="actuator:joint_12.0" joint="joint_12.0" ctrlrange="0 1" kp="10" forcerange="-1 1"></position>
        <position name="actuator:joint_13.0" joint="joint_13.0" ctrlrange="0 1" kp="10" forcerange="-1 1"></position>
        <position name="actuator:joint_14.0" joint="joint_14.0" ctrlrange="0 1" kp="10" forcerange="-1 1"></position>
        <position name="actuator:joint_15.0" joint="joint_15.0" ctrlrange="0 1" kp="10" forcerange="-1 1"></position>
    </actuator>

    <worldbody>
        
        <body mocap="true" name="mocap" pos="0 0 0">
            <geom conaffinity="0" contype="0" pos="0 0 0" rgba="0 0.5 0 0.7" size="0.005 0.005 0.005" type="box"></geom>
            <geom conaffinity="0" contype="0" pos="0 0 0" rgba="0 0.5 0 0.1" size="1 0.005 0.005" type="box"></geom>
            <geom conaffinity="0" contype="0" pos="0 0 0" rgba="0 0.5 0 0.1" size="0.005 1 0.001" type="box"></geom>
            <geom conaffinity="0" contype="0" pos="0 0 0" rgba="0 0.5 0 0.1" size="0.005 0.005 1" type="box"></geom>
	    </body>

		<body name="floor0" pos="0 0.66 -0.44">
			<site name="target0" pos="0 0 0.5" size="0.02 0.02 0.02" rgba="1 0 0 1" type="sphere"></site>
		</body>

        <body pos="0.35 0 -0.2" name="table0">
			<geom size="1.7 1.7 0.2" type="box" mass="2000" material="table_mat" name="table"></geom>
		</body>
        
        
        <!-- <body name="ball" pos="0.8 0.1 0.02">
			<joint name="ball:joint" type="free"></joint>
			<geom size="0.015 0.015 0.03" rgba="1 0 0 1" type="box" condim="3" name="ball" material="block_mat" mass="2"></geom>
			<geom size="0.02 0.02 0.02" rgba="1 0.5 0 1" type="sphere" condim="3" name="ball" mass="0.0002"></geom>
			<site name="ball" pos="0 0 0" size="0.005 0.005 0.005" rgba="1 0 0 1" type="sphere"></site>
		</body> -->
        
        <body name="target" pos="0.6 0. 0.04">
            <freejoint/>
            <composite type="box" count="7 7 7" spacing="0.012">
                <geom type="capsule" size=".0045 0.015" rgba=".8 .2 .1 1"/>
            </composite>
			<site name="target" pos="0 0 0" size="0.005 0.005 0.005" rgba="1 0 0 1" type="sphere"></site>
        </body>

        <!-- <composite type="grid" count="10 1 1" spacing="0.02" offset="0.12 0 0">
            <joint kind="main" damping="0.001" frictionloss="0.5"/>
            <tendon kind="main" width="0.001"/>
            <geom size=".002" rgba=".8 .2 .1 1" mass="1"/>
            <pin coord="0"/>
        </composite> -->

        <!-- <body name="target" pos="0.8 0. 0.02">
			<joint name="target:joint" type="free"></joint>
			<geom size="0.02 0.02 0.02" rgba="1 0 0 1" type="box" condim="3" name="target"></geom>
			<site name="target" pos="0 0 0" size="0.005 0.005 0.005" rgba="1 0 0 1" type="sphere"></site>
		</body> -->

        
        <body name="link" pos="0 0 0">
            <geom type="mesh" contype="0" conaffinity="0" group="1" mesh="A0509_0_0" />
            <body name="link1" pos="0 0 0.1555">
                <inertial pos="7e-05 0.044281 0.143327" quat="0.43643 0.523178 -0.561691 0.469379" mass="7.446" diaginertia="0.0395468 0.0389972 0.022456" />
                <joint name="joint1" pos="0 0 0" axis="0 0 1" limited="true" range="-180 180" />
                <geom type="mesh" contype="0" conaffinity="0" group="1" mesh="A0509_1_0" />
                <geom type="mesh" contype="0" conaffinity="0" group="1" mesh="A0509_1_1" />
                <geom type="mesh" contype="0" conaffinity="0" group="1" mesh="A0509_1_2" />
                <body name="link2" pos="0 0 0" quat="0.499898 -0.500102 -0.5 -0.5">
                    <inertial pos="-1.6e-05 0.189372 0.418558" quat="0.765408 -0.00377271 0.00338956 0.643525" mass="10.569" diaginertia="0.820084 0.819998 0.0309188" />
                    <joint name="joint2" pos="0 0 0" axis="0 0 1" limited="true" range="-180 180" />
                    <geom type="mesh" contype="0" conaffinity="0" group="1" mesh="A0509_2_0" />
                    <geom type="mesh" contype="0" conaffinity="0" group="1" mesh="A0509_2_1" />
                    <geom type="mesh" contype="0" conaffinity="0" group="1" mesh="A0509_2_2" />
                    <body name="link3" pos="0.409 0 0" quat="0.707035 0 0 0.707179">
                        <inertial pos="6e-06 0.07917 0.781807" quat="0.785861 0.485841 0.200877 -0.32562" mass="3.614" diaginertia="0.012003 0.011997 0.007" />
                        <joint name="joint3" pos="0 0 0" axis="0 0 1" limited="true" range="-180 180" />
                        <geom type="mesh" contype="0" conaffinity="0" group="1" mesh="A0509_3_0" />
                        <geom type="mesh" contype="0" conaffinity="0" group="1" mesh="A0509_3_1" />
                        <body name="link4" pos="0 -0.367 0" quat="0.707035 0.707179 0 0">
                            <inertial pos="-2.1e-05 0.12337 1.148" quat="0.696384 -0.109451 0.110147 0.70067" mass="3.785" diaginertia="0.177117 0.177 0.00588312" />
                            <joint name="joint4" pos="0 0 0" axis="0 0 1" limited="true" range="-180 180" />
                            <geom type="mesh" contype="0" conaffinity="0" group="1" mesh="A0509_4_0" />
                            <geom type="mesh" contype="0" conaffinity="0" group="1" mesh="A0509_4_1" />
                            <body name="link5" pos="0 0 0" quat="0.707035 -0.707179 0 0">
                                <inertial pos="-1.7e-05 0.06662 1.33103" quat="0.289458 0.294837 -0.651253 0.636517" mass="2.598" diaginertia="0.00700625 0.00699523 0.00399852" />
                                <joint name="joint5" pos="0 0 0" axis="0 0 1" limited="true" range="-180 180" />
                                <geom type="mesh" contype="0" conaffinity="0" group="1" mesh="A0509_5_0" />
                                <geom type="mesh" contype="0" conaffinity="0" group="1" mesh="A0509_5_1" />
                                <body name="link6" pos="0 -0.124 0" quat="0.707035 0.707179 0 0">
                                    <inertial pos="-0.000174 0.034708 1.40022" quat="0.3881 -0.303109 0.170502 0.853482" mass="1.128" diaginertia="0.00101032 0.000997245 0.000992434" />
                                    <!-- <body name="mocap_body" pos="0.0 0.0 0.0"> -->
                                    <!-- <joint name="joint6" pos="0 0 0" axis="0 0 1" limited="true" range="45.0 135.01" stiffness="0" /> -->
                                    <!-- <joint name="joint6" pos="0 0 0" axis="0 0 1" limited="true" range="-0 0.01" stiffness="10000" /> -->
                                    <geom type="mesh" contype="0" conaffinity="0" group="1" mesh="A0509_6_0" />
                                    <!-- <body name="mocap_body" pos="0.0 0.0 0.0">
                                        <site name="grip" pos="0.0 0 0" rgba="0 0 0 0" size="0.02 0.02 0.02"></site>
                                    </body>                          -->                                        
                                    <!-- <body pos="0.04 0.075 0.08" name="tray">
                                        <geom pos="0. -0.11 -0." size="0.02 0.1 0.02" type="box" rgba="0 0 0 1" material="table_mat"></geom>  
                                        <geom pos="0. -0.2 0.04" size="0.02 0.01 0.02" type="box" rgba="0 0 0 1" material="table_mat"></geom>  
                                    </body> -->
                                    <body name="alle_base_body" pos="0.0 0.0 0.1">
                                        <site name="palm" pos="0.0 0 0" rgba="0 0 0 0" size="0.02 0.02 0.02"></site>
                                        <geom type="mesh" contype="0" conaffinity="0" group="1" rgba="0.2 0.2 0.2 1" mesh="base_link" />
                                        <geom contype="0" conaffinity="0" group="1" size="0.0204 0.0565 0.0475" pos="-0.0093 0 -0.0475" type="box" rgba="0.2 0.2 0.2 1" />
                                        <body name="link_0.0" pos="0 0.0435 -0.001542" quat="0.999048 -0.0436194 0 0">
                                            <inertial pos="0 0 0" quat="0.707107 0.707107 0 0" mass="0.0119" diaginertia="1.01667e-06 1.01667e-06 6.47677e-07" />
                                            <joint name="joint_0.0" pos="0 0 0" axis="0 0 1" limited="true" range="-32.65 32.65" damping="3" frictionloss="10" />
                                            <geom type="mesh" contype="0" conaffinity="0" group="1" rgba="0.2 0.2 0.2 1" mesh="link_0.0" />
                                            <geom contype="0" conaffinity="0" group="1" size="0.0098 0.01375 0.0082" pos="0 0 0.0082" type="box" rgba="0.2 0.2 0.2 1" />
                                            <body name="link_1.0" pos="0 0 0.0164">
                                                <inertial pos="0 0 0" quat="0.702596 0.559386 -0.178354 0.402039" mass="0.065" diaginertia="6.12799e-05 6.12799e-05 6.12799e-05" />
                                                <joint name="joint_1.0" pos="0 0 0" axis="0 1 0" limited="true" range="-16.95 97.97" damping="3" frictionloss="5" />
                                                <geom type="mesh" contype="0" conaffinity="0" group="1" rgba="0.2 0.2 0.2 1" mesh="link_1.0" />
                                                <geom size="0.0098 0.01375 0.027" pos="0 0 0.027" type="box" rgba="0.2 0.2 0.2 1" />
                                                <body name="link_2.0" pos="0 0 0.054">
                                                    <inertial pos="0 0 0" quat="0.719796 0.528175 -0.157463 0.422055" mass="0.0355" diaginertia="2.20969e-05 2.20969e-05 2.20969e-05" />
                                                    <joint name="joint_2.0" pos="0 0 0" axis="0 1 0" limited="true" range="-15.69 103.65" damping="8" frictionloss="10" />
                                                    <geom type="mesh" contype="0" conaffinity="0" group="1" rgba="0.2 0.2 0.2 1" mesh="link_2.0" />
                                                    <geom size="0.0098 0.01375 0.0192" pos="0 0 0.0192" type="box" rgba="0.2 0.2 0.2 1" />
                                                    <body name="link_3.0" pos="0 0 0.0384">
                                                        <inertial pos="0 0 0.0169909" mass="0.0264" diaginertia="9.67371e-06 9.67371e-06 5.3186e-06" />
                                                        <joint name="joint_3.0" pos="0 0 0" axis="0 1 0" limited="true" range="-18.73 98.43" damping="10" frictionloss="12" />
                                                        <geom type="mesh" contype="0" conaffinity="0" group="1" rgba="0.2 0.2 0.2 1" mesh="link_3.0" />
                                                        <geom size="0.0098 0.01375 0.01335" pos="0 0 0.01335" type="box" rgba="0.2 0.2 0.2 1" />
                                                        <geom pos="0 0 0.0267" type="mesh" rgba="0.9 0.9 0.9 1" mesh="link_3.0_tip" />
                                                        <geom size="0.012" pos="0 0 0.0267" rgba="0.9 0.9 0.9 1" />
                                                        <body name="ftip1_body" pos="0 0 0.0267"></body>
                                                        <site name="ftip1" pos="0 0 0.0267" group="3"></site>
                                                    </body>
                                                </body>
                                            </body>
                                        </body>
                                        <body name="link_4.0" pos="0 0 0.0007">
                                            <inertial pos="0 0 0" quat="0.707107 0.707107 0 0" mass="0.0119" diaginertia="1.01667e-06 1.01667e-06 6.47677e-07" />
                                            <joint name="joint_4.0" pos="0 0 0" axis="0 0 1" limited="true" range="-32.65 32.65" damping="3" frictionloss="10" />
                                            <geom type="mesh" contype="0" conaffinity="0" group="1" rgba="0.2 0.2 0.2 1" mesh="link_0.0" />
                                            <geom contype="0" conaffinity="0" group="1" size="0.0098 0.01375 0.0082" pos="0 0 0.0082" type="box" rgba="0.2 0.2 0.2 1" />
                                            <body name="link_5.0" pos="0 0 0.0164">
                                                <inertial pos="0 0 0" quat="0.702596 0.559386 -0.178354 0.402039" mass="0.065" diaginertia="6.12799e-05 6.12799e-05 6.12799e-05" />
                                                <joint name="joint_5.0" pos="0 0 0" axis="0 1 0" limited="true" range="-16.95 97.97" damping="3" frictionloss="5" />
                                                <geom type="mesh" contype="0" conaffinity="0" group="1" rgba="0.2 0.2 0.2 1" mesh="link_1.0" />
                                                <geom size="0.0098 0.01375 0.027" pos="0 0 0.027" type="box" rgba="0.2 0.2 0.2 1" />
                                                <body name="link_6.0" pos="0 0 0.054">
                                                    <inertial pos="0 0 0" quat="0.719796 0.528175 -0.157463 0.422055" mass="0.0355" diaginertia="2.20969e-05 2.20969e-05 2.20969e-05" />
                                                    <joint name="joint_6.0" pos="0 0 0" axis="0 1 0" limited="true" range="-15.69 103.65" damping="8" frictionloss="10" />
                                                    <geom type="mesh" contype="0" conaffinity="0" group="1" rgba="0.2 0.2 0.2 1" mesh="link_2.0" />
                                                    <geom size="0.0098 0.01375 0.0192" pos="0 0 0.0192" type="box" rgba="0.2 0.2 0.2 1" />
                                                    <body name="link_7.0" pos="0 0 0.0384">
                                                        <inertial pos="0 0 0.0169909" mass="0.0264" diaginertia="9.67371e-06 9.67371e-06 5.3186e-06" />
                                                        <joint name="joint_7.0" pos="0 0 0" axis="0 1 0" limited="true" range="-18.73 98.43" damping="10" frictionloss="12" />
                                                        <geom type="mesh" contype="0" conaffinity="0" group="1" rgba="0.2 0.2 0.2 1" mesh="link_3.0" />
                                                        <geom size="0.0098 0.01375 0.01335" pos="0 0 0.01335" type="box" rgba="0.2 0.2 0.2 1" />
                                                        <geom pos="0 0 0.0267" type="mesh" rgba="0.9 0.9 0.9 1" mesh="link_3.0_tip" />
                                                        <geom size="0.012" pos="0 0 0.0267" rgba="0.9 0.9 0.9 1" />
                                                        <body name="ftip2" pos="0 0 0.0267"></body>
                                                        <site name="ftip2" pos="0 0 0.0267" group="3"></site>
                                                    </body>
                                                </body>
                                            </body>
                                        </body>
                                        <body name="link_8.0" pos="0 -0.0435 -0.001542" quat="0.999048 0.0436194 0 0">
                                            <inertial pos="0 0 0" quat="0.707107 0.707107 0 0" mass="0.0119" diaginertia="1.01667e-06 1.01667e-06 6.47677e-07" />
                                            <joint name="joint_8.0" pos="0 0 0" axis="0 0 1" limited="true" range="-32.65 32.65" damping="3" frictionloss="10" />
                                            <geom type="mesh" contype="0" conaffinity="0" group="1" rgba="0.2 0.2 0.2 1" mesh="link_0.0" />
                                            <geom contype="0" conaffinity="0" group="1" size="0.0098 0.01375 0.0082" pos="0 0 0.0082" type="box" rgba="0.2 0.2 0.2 1" />
                                            <body name="link_9.0" pos="0 0 0.0164">
                                                <inertial pos="0 0 0" quat="0.702596 0.559386 -0.178354 0.402039" mass="0.065" diaginertia="6.12799e-05 6.12799e-05 6.12799e-05" />
                                                <joint name="joint_9.0" pos="0 0 0" axis="0 1 0" limited="true" range="-16.95 97.97" damping="3" frictionloss="5" />
                                                <geom type="mesh" contype="0" conaffinity="0" group="1" rgba="0.2 0.2 0.2 1" mesh="link_1.0" />
                                                <geom size="0.0098 0.01375 0.027" pos="0 0 0.027" type="box" rgba="0.2 0.2 0.2 1" />
                                                <body name="link_10.0" pos="0 0 0.054">
                                                    <inertial pos="0 0 0" quat="0.719796 0.528175 -0.157463 0.422055" mass="0.0355" diaginertia="2.20969e-05 2.20969e-05 2.20969e-05" />
                                                    <joint name="joint_10.0" pos="0 0 0" axis="0 1 0" limited="true" range="-15.69 103.65" damping="8" frictionloss="10" />
                                                    <geom type="mesh" contype="0" conaffinity="0" group="1" rgba="0.2 0.2 0.2 1" mesh="link_2.0" />
                                                    <geom size="0.0098 0.01375 0.0192" pos="0 0 0.0192" type="box" rgba="0.2 0.2 0.2 1" />
                                                    <body name="link_11.0" pos="0 0 0.0384">
                                                        <inertial pos="0 0 0.0169909" mass="0.0264" diaginertia="9.67371e-06 9.67371e-06 5.3186e-06" />
                                                        <joint name="joint_11.0" pos="0 0 0" axis="0 1 0" limited="true" range="-18.73 98.43" damping="10" frictionloss="12" />
                                                        <geom type="mesh" contype="0" conaffinity="0" group="1" rgba="0.2 0.2 0.2 1" mesh="link_3.0" />
                                                        <geom size="0.0098 0.01375 0.01335" pos="0 0 0.01335" type="box" rgba="0.2 0.2 0.2 1" />
                                                        <geom pos="0 0 0.0267" type="mesh" rgba="0.9 0.9 0.9 1" mesh="link_3.0_tip" />
                                                        <geom size="0.012" pos="0 0 0.0267" rgba="0.9 0.9 0.9 1" />
                                                        <body name="ftip3" pos="0 0 0.0267"></body>
                                                        <site name="ftip3" pos="0 0 0.0267" group="3"></site>
                                                    </body>
                                                </body>
                                            </body>
                                        </body>
                                        <body name="link_12.0" pos="-0.0182 0.019333 -0.045987" quat="0.477714 -0.521334 -0.521334 -0.477714">
                                            <inertial pos="0 0 0" quat="0.692635 0.569362 -0.07143 0.437013" mass="0.0176" diaginertia="1.73852e-05 1.73852e-05 1.73852e-05" />
                                            <!-- <joint name="joint_12.0" pos="0 0 0" axis="-1 0 0" limited="true" range="0.263 1.396" damping="3" frictionloss="10" /> -->
                                            <joint name="joint_12.0" pos="0 0 0" axis="-1 0 0" limited="true" range="20.62 85.71" damping="3" frictionloss="10" />
                                            <geom quat="8.94897e-10 1 0 0" type="mesh" contype="0" conaffinity="0" group="1" rgba="0.2 0.2 0.2 1" mesh="link_12.0_right" />
                                            <geom contype="0" conaffinity="0" group="1" size="0.0179 0.017 0.02275" pos="-0.0179 0.009 0.0145" type="box" rgba="0.2 0.2 0.2 1" />
                                            <body name="link_13.0" pos="-0.027 0.005 0.0399">
                                                <inertial pos="0 0 0" quat="-0.0269589 0.880876 0.334036 0.334292" mass="0.0119" diaginertia="4.33621e-06 4.33621e-06 4.33621e-06" />
                                                <!-- <joint name="joint_13.0" pos="0 0 0" axis="0 0 1" limited="true" range="-0.105 1.163" damping="3" frictionloss="5" /> -->
                                                <joint name="joint_13.0" pos="0 0 0" axis="0 0 1" limited="true" range="-11.68 72.36" damping="3" frictionloss="5" />
                                                <geom type="mesh" contype="0" conaffinity="0" group="1" rgba="0.2 0.2 0.2 1" mesh="link_13.0" />
                                                <geom size="0.0098 0.01375 0.00885" pos="0 0 0.00885" type="box" rgba="0.2 0.2 0.2 1" />
                                                <body name="link_14.0" pos="0 0 0.0177">
                                                    <inertial pos="0 0 0" quat="0.70472 0.55555 -0.174905 0.405146" mass="0.038" diaginertia="3.35111e-05 3.35111e-05 3.35111e-05" />
                                                    <!-- <joint name="joint_14.0" pos="0 0 0" axis="0 1 0" limited="true" range="-0.189 1.644" damping="3" frictionloss="10" /> -->
                                                    <joint name="joint_14.0" pos="0 0 0" axis="0 1 0" limited="true" range="-16.55 99.92" damping="3" frictionloss="10" />
                                                    <geom type="mesh" contype="0" conaffinity="0" group="1" rgba="0.2 0.2 0.2 1" mesh="link_14.0" />
                                                    <geom size="0.0098 0.01375 0.0257" pos="0 0 0.0257" type="box" rgba="0.2 0.2 0.2 1" />
                                                    <body name="link_15.0" pos="0 0 0.0514">
                                                        <inertial pos="0 0 0.0127813" quat="0.707107 0 0 0.707107" mass="0.0556" diaginertia="4.88098e-05 4.88098e-05 2.78326e-05" />
                                                        <!-- <joint name="joint_15.0" pos="0 0 0" axis="0 1 0" limited="true" range="-0.162 1.719" damping="3" frictionloss="12" /> -->
                                                        <joint name="joint_15.0" pos="0 0 0" axis="0 1 0" limited="true" range="-14.89 103.22" damping="3" frictionloss="12" />
                                                        <geom type="mesh" contype="0" conaffinity="0" group="1" rgba="0.2 0.2 0.2 1" mesh="link_15.0" />
                                                        <geom size="0.0098 0.01375 0.02115" pos="0 0 0.02115" type="box" rgba="0.2 0.2 0.2 1" />
                                                        <geom pos="0 0 0.0423" type="mesh" rgba="0.9 0.9 0.9 1" mesh="link_15.0_tip" />
                                                        <body name="ftip4" pos="0 0 0.0423"></body>
                                                        <site name="ftip4" pos="0 0 0.0423" group="3"></site>
                                                    </body>
                                                </body>
                                            </body>
                                        </body>         
                                    </body>                                  
                                    <!-- </body>                                -->
                                </body>
                            </body>
                        </body>
                    </body>
                </body>
            </body>
        </body>
        <light directional="true" ambient="0.2 0.2 0.2" diffuse="0.8 0.8 0.8" specular="0.3 0.3 0.3" castshadow="false" pos="0 0 4" dir="0 0 -1" name="light0"></light>
    </worldbody>
</mujoco>
